2024-05-31 14:05:02 INFO: Scrapy 2.11.1 started (bot: scraping)
2024-05-31 14:05:02 INFO: Versions: lxml 5.2.1.0, libxml2 2.12.6, cssselect 1.2.0, parsel 1.9.1, w3lib 2.1.2, Twisted 24.3.0, Python 3.10.12 (main, Jun 13 2023, 15:57:17) [GCC 8.3.0], pyOpenSSL 24.1.0 (OpenSSL 3.2.1 30 Jan 2024), cryptography 42.0.5, Platform Linux-6.5.0-35-generic-x86_64-with-glibc2.28
2024-05-31 14:05:02 INFO: Enabled addons:
[]
2024-05-31 14:05:02 DEBUG: Using selector: EpollSelector
2024-05-31 14:05:02 DEBUG: Using reactor: twisted.internet.asyncioreactor.AsyncioSelectorReactor
2024-05-31 14:05:02 DEBUG: Using asyncio event loop: asyncio.unix_events._UnixSelectorEventLoop
2024-05-31 14:05:02 INFO: Telnet Password: d21e718253bb9e1c
2024-05-31 14:05:02 INFO: Enabled extensions:
['scrapy.extensions.corestats.CoreStats',
 'scrapy.extensions.telnet.TelnetConsole',
 'scrapy.extensions.memusage.MemoryUsage',
 'scrapy.extensions.logstats.LogStats']
2024-05-31 14:05:02 INFO: Overridden settings:
{'BOT_NAME': 'scraping',
 'CONCURRENT_REQUESTS_PER_DOMAIN': 1,
 'DOWNLOAD_DELAY': 2,
 'FEED_EXPORT_ENCODING': 'utf-8',
 'NEWSPIDER_MODULE': 'scraping.spiders',
 'REQUEST_FINGERPRINTER_IMPLEMENTATION': '2.7',
 'ROBOTSTXT_OBEY': True,
 'SPIDER_MODULES': ['scraping.spiders'],
 'TWISTED_REACTOR': 'twisted.internet.asyncioreactor.AsyncioSelectorReactor',
 'USER_AGENT': 'Mozilla/5.0 (Windows NT 10.0; Win64; x64) AppleWebKit/537.36 '
               '(KHTML, like Gecko) Chrome/93.0.4577.82 Safari/537.36'}
2024-05-31 14:05:02 DEBUG: Not in REPL -> leaving logger event level as is.
2024-05-31 14:05:02 INFO: Error loading User-Agent provider: scrapy_fake_useragent.providers.FakeUserAgentProvider
2024-05-31 14:05:02 DEBUG: Looking for locale `en_US` in provider `faker.providers.address`.
2024-05-31 14:05:02 DEBUG: Provider `faker.providers.address` has been localized to `en_US`.
2024-05-31 14:05:02 DEBUG: Looking for locale `en_US` in provider `faker.providers.automotive`.
2024-05-31 14:05:02 DEBUG: Provider `faker.providers.automotive` has been localized to `en_US`.
2024-05-31 14:05:02 DEBUG: Looking for locale `en_US` in provider `faker.providers.bank`.
2024-05-31 14:05:02 DEBUG: Specified locale `en_US` is not available for provider `faker.providers.bank`. Locale reset to `en_GB` for this provider.
2024-05-31 14:05:02 DEBUG: Looking for locale `en_US` in provider `faker.providers.barcode`.
2024-05-31 14:05:02 DEBUG: Provider `faker.providers.barcode` has been localized to `en_US`.
2024-05-31 14:05:02 DEBUG: Looking for locale `en_US` in provider `faker.providers.color`.
2024-05-31 14:05:02 DEBUG: Provider `faker.providers.color` has been localized to `en_US`.
2024-05-31 14:05:02 DEBUG: Looking for locale `en_US` in provider `faker.providers.company`.
2024-05-31 14:05:02 DEBUG: Provider `faker.providers.company` has been localized to `en_US`.
2024-05-31 14:05:02 DEBUG: Looking for locale `en_US` in provider `faker.providers.credit_card`.
2024-05-31 14:05:02 DEBUG: Provider `faker.providers.credit_card` has been localized to `en_US`.
2024-05-31 14:05:02 DEBUG: Looking for locale `en_US` in provider `faker.providers.currency`.
2024-05-31 14:05:02 DEBUG: Provider `faker.providers.currency` has been localized to `en_US`.
2024-05-31 14:05:02 DEBUG: Looking for locale `en_US` in provider `faker.providers.date_time`.
2024-05-31 14:05:02 DEBUG: Provider `faker.providers.date_time` has been localized to `en_US`.
2024-05-31 14:05:02 DEBUG: Provider `faker.providers.emoji` does not feature localization. Specified locale `en_US` is not utilized for this provider.
2024-05-31 14:05:02 DEBUG: Provider `faker.providers.file` does not feature localization. Specified locale `en_US` is not utilized for this provider.
2024-05-31 14:05:02 DEBUG: Looking for locale `en_US` in provider `faker.providers.geo`.
2024-05-31 14:05:02 DEBUG: Provider `faker.providers.geo` has been localized to `en_US`.
2024-05-31 14:05:02 DEBUG: Looking for locale `en_US` in provider `faker.providers.internet`.
2024-05-31 14:05:02 DEBUG: Provider `faker.providers.internet` has been localized to `en_US`.
2024-05-31 14:05:02 DEBUG: Provider `faker.providers.isbn` does not feature localization. Specified locale `en_US` is not utilized for this provider.
2024-05-31 14:05:02 DEBUG: Looking for locale `en_US` in provider `faker.providers.job`.
2024-05-31 14:05:02 DEBUG: Provider `faker.providers.job` has been localized to `en_US`.
2024-05-31 14:05:02 DEBUG: Looking for locale `en_US` in provider `faker.providers.lorem`.
2024-05-31 14:05:02 DEBUG: Provider `faker.providers.lorem` has been localized to `en_US`.
2024-05-31 14:05:02 DEBUG: Looking for locale `en_US` in provider `faker.providers.misc`.
2024-05-31 14:05:02 DEBUG: Provider `faker.providers.misc` has been localized to `en_US`.
2024-05-31 14:05:02 DEBUG: Looking for locale `en_US` in provider `faker.providers.passport`.
2024-05-31 14:05:02 DEBUG: Provider `faker.providers.passport` has been localized to `en_US`.
2024-05-31 14:05:02 DEBUG: Looking for locale `en_US` in provider `faker.providers.person`.
2024-05-31 14:05:02 DEBUG: Provider `faker.providers.person` has been localized to `en_US`.
2024-05-31 14:05:02 DEBUG: Looking for locale `en_US` in provider `faker.providers.phone_number`.
2024-05-31 14:05:02 DEBUG: Provider `faker.providers.phone_number` has been localized to `en_US`.
2024-05-31 14:05:02 DEBUG: Provider `faker.providers.profile` does not feature localization. Specified locale `en_US` is not utilized for this provider.
2024-05-31 14:05:02 DEBUG: Provider `faker.providers.python` does not feature localization. Specified locale `en_US` is not utilized for this provider.
2024-05-31 14:05:02 DEBUG: Provider `faker.providers.sbn` does not feature localization. Specified locale `en_US` is not utilized for this provider.
2024-05-31 14:05:02 DEBUG: Looking for locale `en_US` in provider `faker.providers.ssn`.
2024-05-31 14:05:02 DEBUG: Provider `faker.providers.ssn` has been localized to `en_US`.
2024-05-31 14:05:02 DEBUG: Provider `faker.providers.user_agent` does not feature localization. Specified locale `en_US` is not utilized for this provider.
2024-05-31 14:05:02 DEBUG: Loaded User-Agent provider: scrapy_fake_useragent.providers.FakerProvider
2024-05-31 14:05:02 INFO: Using '<class 'scrapy_fake_useragent.providers.FakerProvider'>' as the User-Agent provider
2024-05-31 14:05:02 INFO: Error loading User-Agent provider: scrapy_fake_useragent.providers.FakeUserAgentProvider
2024-05-31 14:05:02 DEBUG: Looking for locale `en_US` in provider `faker.providers.address`.
2024-05-31 14:05:02 DEBUG: Provider `faker.providers.address` has been localized to `en_US`.
2024-05-31 14:05:02 DEBUG: Looking for locale `en_US` in provider `faker.providers.automotive`.
2024-05-31 14:05:02 DEBUG: Provider `faker.providers.automotive` has been localized to `en_US`.
2024-05-31 14:05:02 DEBUG: Looking for locale `en_US` in provider `faker.providers.bank`.
2024-05-31 14:05:02 DEBUG: Specified locale `en_US` is not available for provider `faker.providers.bank`. Locale reset to `en_GB` for this provider.
2024-05-31 14:05:02 DEBUG: Looking for locale `en_US` in provider `faker.providers.barcode`.
2024-05-31 14:05:02 DEBUG: Provider `faker.providers.barcode` has been localized to `en_US`.
2024-05-31 14:05:02 DEBUG: Looking for locale `en_US` in provider `faker.providers.color`.
2024-05-31 14:05:02 DEBUG: Provider `faker.providers.color` has been localized to `en_US`.
2024-05-31 14:05:02 DEBUG: Looking for locale `en_US` in provider `faker.providers.company`.
2024-05-31 14:05:02 DEBUG: Provider `faker.providers.company` has been localized to `en_US`.
2024-05-31 14:05:02 DEBUG: Looking for locale `en_US` in provider `faker.providers.credit_card`.
2024-05-31 14:05:02 DEBUG: Provider `faker.providers.credit_card` has been localized to `en_US`.
2024-05-31 14:05:02 DEBUG: Looking for locale `en_US` in provider `faker.providers.currency`.
2024-05-31 14:05:02 DEBUG: Provider `faker.providers.currency` has been localized to `en_US`.
2024-05-31 14:05:02 DEBUG: Looking for locale `en_US` in provider `faker.providers.date_time`.
2024-05-31 14:05:02 DEBUG: Provider `faker.providers.date_time` has been localized to `en_US`.
2024-05-31 14:05:02 DEBUG: Provider `faker.providers.emoji` does not feature localization. Specified locale `en_US` is not utilized for this provider.
2024-05-31 14:05:02 DEBUG: Provider `faker.providers.file` does not feature localization. Specified locale `en_US` is not utilized for this provider.
2024-05-31 14:05:02 DEBUG: Looking for locale `en_US` in provider `faker.providers.geo`.
2024-05-31 14:05:02 DEBUG: Provider `faker.providers.geo` has been localized to `en_US`.
2024-05-31 14:05:02 DEBUG: Looking for locale `en_US` in provider `faker.providers.internet`.
2024-05-31 14:05:02 DEBUG: Provider `faker.providers.internet` has been localized to `en_US`.
2024-05-31 14:05:02 DEBUG: Provider `faker.providers.isbn` does not feature localization. Specified locale `en_US` is not utilized for this provider.
2024-05-31 14:05:02 DEBUG: Looking for locale `en_US` in provider `faker.providers.job`.
2024-05-31 14:05:02 DEBUG: Provider `faker.providers.job` has been localized to `en_US`.
2024-05-31 14:05:02 DEBUG: Looking for locale `en_US` in provider `faker.providers.lorem`.
2024-05-31 14:05:02 DEBUG: Provider `faker.providers.lorem` has been localized to `en_US`.
2024-05-31 14:05:02 DEBUG: Looking for locale `en_US` in provider `faker.providers.misc`.
2024-05-31 14:05:02 DEBUG: Provider `faker.providers.misc` has been localized to `en_US`.
2024-05-31 14:05:02 DEBUG: Looking for locale `en_US` in provider `faker.providers.passport`.
2024-05-31 14:05:02 DEBUG: Provider `faker.providers.passport` has been localized to `en_US`.
2024-05-31 14:05:02 DEBUG: Looking for locale `en_US` in provider `faker.providers.person`.
2024-05-31 14:05:02 DEBUG: Provider `faker.providers.person` has been localized to `en_US`.
2024-05-31 14:05:02 DEBUG: Looking for locale `en_US` in provider `faker.providers.phone_number`.
2024-05-31 14:05:02 DEBUG: Provider `faker.providers.phone_number` has been localized to `en_US`.
2024-05-31 14:05:02 DEBUG: Provider `faker.providers.profile` does not feature localization. Specified locale `en_US` is not utilized for this provider.
2024-05-31 14:05:02 DEBUG: Provider `faker.providers.python` does not feature localization. Specified locale `en_US` is not utilized for this provider.
2024-05-31 14:05:02 DEBUG: Provider `faker.providers.sbn` does not feature localization. Specified locale `en_US` is not utilized for this provider.
2024-05-31 14:05:02 DEBUG: Looking for locale `en_US` in provider `faker.providers.ssn`.
2024-05-31 14:05:02 DEBUG: Provider `faker.providers.ssn` has been localized to `en_US`.
2024-05-31 14:05:02 DEBUG: Provider `faker.providers.user_agent` does not feature localization. Specified locale `en_US` is not utilized for this provider.
2024-05-31 14:05:02 DEBUG: Loaded User-Agent provider: scrapy_fake_useragent.providers.FakerProvider
2024-05-31 14:05:02 INFO: Using '<class 'scrapy_fake_useragent.providers.FakerProvider'>' as the User-Agent provider
2024-05-31 14:05:02 DEBUG: POST http://chromedriver:4444/session {'capabilities': {'firstMatch': [{}], 'alwaysMatch': {'browserName': 'chrome', 'pageLoadStrategy': <PageLoadStrategy.normal: 'normal'>, 'goog:chromeOptions': {'extensions': [], 'args': []}}}}
2024-05-31 14:05:02 DEBUG: Starting new HTTP connection (1): chromedriver:4444
2024-05-31 14:05:02 DEBUG: Incremented Retry for (url='/session'): Retry(total=2, connect=None, read=None, redirect=None, status=None)
2024-05-31 14:05:02 WARNING: Retrying (Retry(total=2, connect=None, read=None, redirect=None, status=None)) after connection broken by 'NewConnectionError('<urllib3.connection.HTTPConnection object at 0x7df0820d5ba0>: Failed to establish a new connection: [Errno 111] Connection refused')': /session
2024-05-31 14:05:02 DEBUG: Starting new HTTP connection (2): chromedriver:4444
2024-05-31 14:05:02 DEBUG: Incremented Retry for (url='/session'): Retry(total=1, connect=None, read=None, redirect=None, status=None)
2024-05-31 14:05:02 WARNING: Retrying (Retry(total=1, connect=None, read=None, redirect=None, status=None)) after connection broken by 'NewConnectionError('<urllib3.connection.HTTPConnection object at 0x7df0820d5990>: Failed to establish a new connection: [Errno 111] Connection refused')': /session
2024-05-31 14:05:02 DEBUG: Starting new HTTP connection (3): chromedriver:4444
2024-05-31 14:05:02 DEBUG: Incremented Retry for (url='/session'): Retry(total=0, connect=None, read=None, redirect=None, status=None)
2024-05-31 14:05:02 WARNING: Retrying (Retry(total=0, connect=None, read=None, redirect=None, status=None)) after connection broken by 'NewConnectionError('<urllib3.connection.HTTPConnection object at 0x7df0820d57e0>: Failed to establish a new connection: [Errno 111] Connection refused')': /session
2024-05-31 14:05:02 DEBUG: Starting new HTTP connection (4): chromedriver:4444
2024-05-31 14:05:02 CRITICAL: Unhandled error in Deferred:
2024-05-31 14:05:02 CRITICAL: Unhandled error in Deferred:
2024-05-31 14:05:02 CRITICAL: 
Traceback (most recent call last):
  File "/usr/local/lib/python3.10/site-packages/urllib3/connection.py", line 198, in _new_conn
    sock = connection.create_connection(
  File "/usr/local/lib/python3.10/site-packages/urllib3/util/connection.py", line 85, in create_connection
    raise err
  File "/usr/local/lib/python3.10/site-packages/urllib3/util/connection.py", line 73, in create_connection
    sock.connect(sa)
ConnectionRefusedError: [Errno 111] Connection refused

The above exception was the direct cause of the following exception:

Traceback (most recent call last):
  File "/usr/local/lib/python3.10/site-packages/urllib3/connectionpool.py", line 793, in urlopen
    response = self._make_request(
  File "/usr/local/lib/python3.10/site-packages/urllib3/connectionpool.py", line 496, in _make_request
    conn.request(
  File "/usr/local/lib/python3.10/site-packages/urllib3/connection.py", line 400, in request
    self.endheaders()
  File "/usr/local/lib/python3.10/http/client.py", line 1278, in endheaders
    self._send_output(message_body, encode_chunked=encode_chunked)
  File "/usr/local/lib/python3.10/http/client.py", line 1038, in _send_output
    self.send(msg)
  File "/usr/local/lib/python3.10/http/client.py", line 976, in send
    self.connect()
  File "/usr/local/lib/python3.10/site-packages/urllib3/connection.py", line 238, in connect
    self.sock = self._new_conn()
  File "/usr/local/lib/python3.10/site-packages/urllib3/connection.py", line 213, in _new_conn
    raise NewConnectionError(
urllib3.exceptions.NewConnectionError: <urllib3.connection.HTTPConnection object at 0x7df0820d5300>: Failed to establish a new connection: [Errno 111] Connection refused

The above exception was the direct cause of the following exception:

Traceback (most recent call last):
  File "/usr/local/lib/python3.10/site-packages/twisted/internet/defer.py", line 2003, in _inlineCallbacks
    result = context.run(gen.send, result)
  File "/usr/local/lib/python3.10/site-packages/scrapy/crawler.py", line 158, in crawl
    self.engine = self._create_engine()
  File "/usr/local/lib/python3.10/site-packages/scrapy/crawler.py", line 172, in _create_engine
    return ExecutionEngine(self, lambda _: self.stop())
  File "/usr/local/lib/python3.10/site-packages/scrapy/core/engine.py", line 99, in __init__
    self.downloader: Downloader = downloader_cls(crawler)
  File "/usr/local/lib/python3.10/site-packages/scrapy/core/downloader/__init__.py", line 97, in __init__
    DownloaderMiddlewareManager.from_crawler(crawler)
  File "/usr/local/lib/python3.10/site-packages/scrapy/middleware.py", line 90, in from_crawler
    return cls.from_settings(crawler.settings, crawler)
  File "/usr/local/lib/python3.10/site-packages/scrapy/middleware.py", line 67, in from_settings
    mw = create_instance(mwcls, settings, crawler)
  File "/usr/local/lib/python3.10/site-packages/scrapy/utils/misc.py", line 188, in create_instance
    instance = objcls.from_crawler(crawler, *args, **kwargs)
  File "/scraper/scraping/middlewares.py", line 95, in from_crawler
    middleware = cls(
  File "/scraper/scraping/middlewares.py", line 73, in __init__
    self.driver = webdriver.Remote(
  File "/usr/local/lib/python3.10/site-packages/selenium/webdriver/remote/webdriver.py", line 208, in __init__
    self.start_session(capabilities)
  File "/usr/local/lib/python3.10/site-packages/selenium/webdriver/remote/webdriver.py", line 292, in start_session
    response = self.execute(Command.NEW_SESSION, caps)["value"]
  File "/usr/local/lib/python3.10/site-packages/selenium/webdriver/remote/webdriver.py", line 345, in execute
    response = self.command_executor.execute(driver_command, params)
  File "/usr/local/lib/python3.10/site-packages/selenium/webdriver/remote/remote_connection.py", line 302, in execute
    return self._request(command_info[0], url, body=data)
  File "/usr/local/lib/python3.10/site-packages/selenium/webdriver/remote/remote_connection.py", line 322, in _request
    response = self._conn.request(method, url, body=body, headers=headers)
  File "/usr/local/lib/python3.10/site-packages/urllib3/_request_methods.py", line 144, in request
    return self.request_encode_body(
  File "/usr/local/lib/python3.10/site-packages/urllib3/_request_methods.py", line 279, in request_encode_body
    return self.urlopen(method, url, **extra_kw)
  File "/usr/local/lib/python3.10/site-packages/urllib3/poolmanager.py", line 444, in urlopen
    response = conn.urlopen(method, u.request_uri, **kw)
  File "/usr/local/lib/python3.10/site-packages/urllib3/connectionpool.py", line 877, in urlopen
    return self.urlopen(
  File "/usr/local/lib/python3.10/site-packages/urllib3/connectionpool.py", line 877, in urlopen
    return self.urlopen(
  File "/usr/local/lib/python3.10/site-packages/urllib3/connectionpool.py", line 877, in urlopen
    return self.urlopen(
  File "/usr/local/lib/python3.10/site-packages/urllib3/connectionpool.py", line 847, in urlopen
    retries = retries.increment(
  File "/usr/local/lib/python3.10/site-packages/urllib3/util/retry.py", line 515, in increment
    raise MaxRetryError(_pool, url, reason) from reason  # type: ignore[arg-type]
urllib3.exceptions.MaxRetryError: HTTPConnectionPool(host='chromedriver', port=4444): Max retries exceeded with url: /session (Caused by NewConnectionError('<urllib3.connection.HTTPConnection object at 0x7df0820d5300>: Failed to establish a new connection: [Errno 111] Connection refused'))
2024-05-31 14:05:02 CRITICAL: 
Traceback (most recent call last):
  File "/usr/local/lib/python3.10/site-packages/urllib3/connection.py", line 198, in _new_conn
    sock = connection.create_connection(
  File "/usr/local/lib/python3.10/site-packages/urllib3/util/connection.py", line 85, in create_connection
    raise err
  File "/usr/local/lib/python3.10/site-packages/urllib3/util/connection.py", line 73, in create_connection
    sock.connect(sa)
ConnectionRefusedError: [Errno 111] Connection refused

The above exception was the direct cause of the following exception:

Traceback (most recent call last):
  File "/usr/local/lib/python3.10/site-packages/urllib3/connectionpool.py", line 793, in urlopen
    response = self._make_request(
  File "/usr/local/lib/python3.10/site-packages/urllib3/connectionpool.py", line 496, in _make_request
    conn.request(
  File "/usr/local/lib/python3.10/site-packages/urllib3/connection.py", line 400, in request
    self.endheaders()
  File "/usr/local/lib/python3.10/http/client.py", line 1278, in endheaders
    self._send_output(message_body, encode_chunked=encode_chunked)
  File "/usr/local/lib/python3.10/http/client.py", line 1038, in _send_output
    self.send(msg)
  File "/usr/local/lib/python3.10/http/client.py", line 976, in send
    self.connect()
  File "/usr/local/lib/python3.10/site-packages/urllib3/connection.py", line 238, in connect
    self.sock = self._new_conn()
  File "/usr/local/lib/python3.10/site-packages/urllib3/connection.py", line 213, in _new_conn
    raise NewConnectionError(
urllib3.exceptions.NewConnectionError: <urllib3.connection.HTTPConnection object at 0x7df0820d5300>: Failed to establish a new connection: [Errno 111] Connection refused

The above exception was the direct cause of the following exception:

Traceback (most recent call last):
  File "/usr/local/lib/python3.10/site-packages/twisted/internet/defer.py", line 2003, in _inlineCallbacks
    result = context.run(gen.send, result)
  File "/usr/local/lib/python3.10/site-packages/scrapy/crawler.py", line 158, in crawl
    self.engine = self._create_engine()
  File "/usr/local/lib/python3.10/site-packages/scrapy/crawler.py", line 172, in _create_engine
    return ExecutionEngine(self, lambda _: self.stop())
  File "/usr/local/lib/python3.10/site-packages/scrapy/core/engine.py", line 99, in __init__
    self.downloader: Downloader = downloader_cls(crawler)
  File "/usr/local/lib/python3.10/site-packages/scrapy/core/downloader/__init__.py", line 97, in __init__
    DownloaderMiddlewareManager.from_crawler(crawler)
  File "/usr/local/lib/python3.10/site-packages/scrapy/middleware.py", line 90, in from_crawler
    return cls.from_settings(crawler.settings, crawler)
  File "/usr/local/lib/python3.10/site-packages/scrapy/middleware.py", line 67, in from_settings
    mw = create_instance(mwcls, settings, crawler)
  File "/usr/local/lib/python3.10/site-packages/scrapy/utils/misc.py", line 188, in create_instance
    instance = objcls.from_crawler(crawler, *args, **kwargs)
  File "/scraper/scraping/middlewares.py", line 95, in from_crawler
    middleware = cls(
  File "/scraper/scraping/middlewares.py", line 73, in __init__
    self.driver = webdriver.Remote(
  File "/usr/local/lib/python3.10/site-packages/selenium/webdriver/remote/webdriver.py", line 208, in __init__
    self.start_session(capabilities)
  File "/usr/local/lib/python3.10/site-packages/selenium/webdriver/remote/webdriver.py", line 292, in start_session
    response = self.execute(Command.NEW_SESSION, caps)["value"]
  File "/usr/local/lib/python3.10/site-packages/selenium/webdriver/remote/webdriver.py", line 345, in execute
    response = self.command_executor.execute(driver_command, params)
  File "/usr/local/lib/python3.10/site-packages/selenium/webdriver/remote/remote_connection.py", line 302, in execute
    return self._request(command_info[0], url, body=data)
  File "/usr/local/lib/python3.10/site-packages/selenium/webdriver/remote/remote_connection.py", line 322, in _request
    response = self._conn.request(method, url, body=body, headers=headers)
  File "/usr/local/lib/python3.10/site-packages/urllib3/_request_methods.py", line 144, in request
    return self.request_encode_body(
  File "/usr/local/lib/python3.10/site-packages/urllib3/_request_methods.py", line 279, in request_encode_body
    return self.urlopen(method, url, **extra_kw)
  File "/usr/local/lib/python3.10/site-packages/urllib3/poolmanager.py", line 444, in urlopen
    response = conn.urlopen(method, u.request_uri, **kw)
  File "/usr/local/lib/python3.10/site-packages/urllib3/connectionpool.py", line 877, in urlopen
    return self.urlopen(
  File "/usr/local/lib/python3.10/site-packages/urllib3/connectionpool.py", line 877, in urlopen
    return self.urlopen(
  File "/usr/local/lib/python3.10/site-packages/urllib3/connectionpool.py", line 877, in urlopen
    return self.urlopen(
  File "/usr/local/lib/python3.10/site-packages/urllib3/connectionpool.py", line 847, in urlopen
    retries = retries.increment(
  File "/usr/local/lib/python3.10/site-packages/urllib3/util/retry.py", line 515, in increment
    raise MaxRetryError(_pool, url, reason) from reason  # type: ignore[arg-type]
urllib3.exceptions.MaxRetryError: HTTPConnectionPool(host='chromedriver', port=4444): Max retries exceeded with url: /session (Caused by NewConnectionError('<urllib3.connection.HTTPConnection object at 0x7df0820d5300>: Failed to establish a new connection: [Errno 111] Connection refused'))
